import { Main } from './main'
import { init, handleException } from '../src/utils/usage'
import { error } from './utils/log'
;(async () => {
  const trx = init()
  const main = new Main()
  try {
    await main.init()
  } catch (e) {
    handleException(e)
    error(`An error has occurred: ${e && e.message}`)
  } finally {
    trx.finish()
  }
})()
